<?xml version="1.0" ?>
<!-- =================================================================================== -->
<!-- |    This document was autogenerated by xacro from stikklar.urdf.xacro            | -->
<!-- |    EDITING THIS FILE BY HAND IS NOT RECOMMENDED                                 | -->
<!-- =================================================================================== -->
<robot name="stikklar" xmlns:xacro="http://www.ros.org/wiki/xacro">
  <!-- lambda step: -math.radians(150) + math.radians(step/1024.*300)-->
  <!-- min servo values: 	coxa=60 femur=162 tibia=95-->
  <!-- max servo values: 	coxa=960 femur=850 tibia=1005-->
  <!-- neutral servo values: 	coxa=364 femur=512 tibia=742-->
  <!-- atmic shapes, ax12, bioloids frames F1, F2, F3, F4 -->
  s

    
  <!-- link+join+composite visuals and collisions -->
  <link name="base_link">
    <inertial>
      <mass value="0.00001"/>
      <origin xyz="0 0 0"/>
      <inertia ixx="1.0" ixy="0.0" ixz="0.0" iyy="1.0" iyz="0.0" izz="1.0"/>
    </inertial>
    <visual>
      <origin rpy="0 0 0" xyz="0 0 0"/>
      <geometry>
        <box size="0.14 0.14 0.055"/>
      </geometry>
      <material name="black">
        <color rgba="0.2 0.2 0.2 1.0"/>
      </material>
    </visual>
    <collision>
      <origin rpy="0 0 0" xyz="0 0 0"/>
      <geometry>
        <box size="0.14 0.14 0.055"/>
      </geometry>
    </collision>
  </link>
  <!-- x=red y=green z=blue -->
  <link name="lf_shoulder_link">
    <inertial>
      <mass value="0.00001"/>
      <origin xyz="0 0 0"/>
      <inertia ixx="1.0" ixy="0.0" ixz="0.0" iyy="1.0" iyz="0.0" izz="1.0"/>
    </inertial>
    <collision>
      <origin rpy="0 0 0" xyz="0 0 0"/>
      <geometry>
        <box size="0.028 0.0485 0.065"/>
      </geometry>
    </collision>
    <visual>
      <origin rpy="0 0 0" xyz="0 0 0"/>
      <!-- <material name="green"/> -->
      <material name="grey60">
        <color rgba="0.6 0.6 0.6 1.0"/>
      </material>
      <geometry>
        <mesh filename="package://stikklar_description/meshes/F4.stl" scale="0.001 0.001 0.001"/>
      </geometry>
    </visual>
  </link>
  <joint name="lf_shoulder_joint" type="fixed">
    <origin rpy="1.57079632679 0 0.7853981634" xyz="-0.1 0.1 0"/>
    <parent link="base_link"/>
    <child link="lf_shoulder_link"/>
  </joint>
  <link name="lf_coxa_bone_link">
    <inertial>
      <mass value="0.00001"/>
      <origin xyz="0 0 0"/>
      <inertia ixx="1.0" ixy="0.0" ixz="0.0" iyy="1.0" iyz="0.0" izz="1.0"/>
    </inertial>
    <visual>
      <origin rpy="0 0 3.14159265359" xyz="0 0 0"/>
      <geometry>
        <mesh filename="package://stikklar_description/meshes/ax12.stl" scale="0.001 0.001 0.001"/>
      </geometry>
      <material name="black">
        <color rgba="0.2 0.2 0.2 1.0"/>
      </material>
    </visual>
    <collision>
      <origin rpy="0 0 0" xyz="0 0 0"/>
      <geometry>
        <box size="0.032 0.040 0.0501"/>
      </geometry>
    </collision>
    <collision>
      <origin rpy="0 3.14159265359 0 " xyz="0 0 -0.0415"/>
      <geometry>
        <box size="0.028 0.0485 0.008"/>
      </geometry>
    </collision>
    <visual>
      <origin rpy="0 3.14159265359 0 " xyz="0 0 -0.0415"/>
      <material name="grey60">
        <color rgba="0.6 0.6 0.6 1.0"/>
      </material>
      <geometry>
        <mesh filename="package://stikklar_description/meshes/F3.stl" scale="0.001 0.001 0.001"/>
      </geometry>
    </visual>
    <collision>
      <origin rpy="0 0 1.57079632679 " xyz="0 0 -0.068"/>
      <geometry>
        <box size="0.025 0.0485 0.0375"/>
      </geometry>
    </collision>
    <visual>
      <origin rpy="0 0 1.57079632679 " xyz="0 0 -0.068"/>
      <geometry>
        <mesh filename="package://stikklar_description/meshes/F2.stl" scale="0.001 0.001 0.001"/>
      </geometry>
      <material name="grey60">
        <color rgba="0.6 0.6 0.6 1.0"/>
      </material>
    </visual>
  </link>
  <joint name="lf_coxa_bone_joint" type="revolute">
    <origin rpy="0 0 0" xyz="0 0 0"/>
    <axis xyz="0 1 0"/>
    <limit effort="30" lower="-2.31119772041" upper="2.29074464324" velocity="100"/>
    <parent link="lf_shoulder_link"/>
    <child link="lf_coxa_bone_link"/>
  </joint>
  <link name="lf_femur_bone_link">
    <inertial>
      <mass value="0.00001"/>
      <origin xyz="0 0 0"/>
      <inertia ixx="1.0" ixy="0.0" ixz="0.0" iyy="1.0" iyz="0.0" izz="1.0"/>
    </inertial>
    <visual>
      <origin rpy="0 0 1.57079632679" xyz="0 0 0"/>
      <geometry>
        <mesh filename="package://stikklar_description/meshes/ax12.stl" scale="0.001 0.001 0.001"/>
      </geometry>
      <material name="black">
        <color rgba="0.2 0.2 0.2 1.0"/>
      </material>
    </visual>
    <collision>
      <origin rpy="0 0 0" xyz="0 0 0"/>
      <geometry>
        <box size="0.032 0.040 0.0501"/>
      </geometry>
    </collision>
    <collision>
      <origin rpy="0 3.14159265359 0" xyz="0 0 -0.0415"/>
      <geometry>
        <box size="0.028 0.0485 0.008"/>
      </geometry>
    </collision>
    <visual>
      <origin rpy="0 3.14159265359 0" xyz="0 0 -0.0415"/>
      <material name="grey60">
        <color rgba="0.6 0.6 0.6 1.0"/>
      </material>
      <geometry>
        <mesh filename="package://stikklar_description/meshes/F3.stl" scale="0.001 0.001 0.001"/>
      </geometry>
    </visual>
    <collision>
      <origin rpy="0 0 0" xyz="-0.008 0 -0.0415"/>
      <geometry>
        <box size="0.028 0.0485 0.008"/>
      </geometry>
    </collision>
    <visual>
      <origin rpy="0 0 0" xyz="-0.008 0 -0.0415"/>
      <material name="grey60">
        <color rgba="0.6 0.6 0.6 1.0"/>
      </material>
      <geometry>
        <mesh filename="package://stikklar_description/meshes/F3.stl" scale="0.001 0.001 0.001"/>
      </geometry>
    </visual>
    <visual>
      <origin rpy="3.14159265359 0 -1.57079632679" xyz="-0.008 0 -0.082"/>
      <geometry>
        <mesh filename="package://stikklar_description/meshes/ax12.stl" scale="0.001 0.001 0.001"/>
      </geometry>
      <material name="black">
        <color rgba="0.2 0.2 0.2 1.0"/>
      </material>
    </visual>
    <collision>
      <origin rpy="0 0 0" xyz="-0.008 0 -0.082"/>
      <geometry>
        <box size="0.032 0.040 0.0501"/>
      </geometry>
    </collision>
  </link>
  <joint name="lf_femur_bone_joint" type="revolute">
    <origin rpy="0 0 0" xyz="0 0 -0.068"/>
    <axis xyz="1 0 0"/>
    <limit effort="30" lower="-1.78964425253" upper="1.72828502102" velocity="100"/>
    <parent link="lf_coxa_bone_link"/>
    <child link="lf_femur_bone_link"/>
  </joint>
  <link name="lf_tibia_bone_link">
    <inertial>
      <mass value="0.00001"/>
      <origin xyz="0 0 0"/>
      <inertia ixx="1.0" ixy="0.0" ixz="0.0" iyy="1.0" iyz="0.0" izz="1.0"/>
    </inertial>
    <collision>
      <origin rpy="0 3.14159265359 1.57079632679" xyz="-0.008 0 0"/>
      <geometry>
        <box size="0.028 0.0485 0.065"/>
      </geometry>
    </collision>
    <visual>
      <origin rpy="0 3.14159265359 1.57079632679" xyz="-0.008 0 0"/>
      <!-- <material name="green"/> -->
      <material name="grey60">
        <color rgba="0.6 0.6 0.6 1.0"/>
      </material>
      <geometry>
        <mesh filename="package://stikklar_description/meshes/F4.stl" scale="0.001 0.001 0.001"/>
      </geometry>
    </visual>
    <collision>
      <origin rpy="-1.57079632679 0 1.57079632679" xyz="-0.0985"/>
      <geometry>
        <box size="0.04 0.028 0.046"/>
      </geometry>
    </collision>
    <visual>
      <origin rpy="-1.57079632679 0 1.57079632679" xyz="-0.0985"/>
      <geometry>
        <mesh filename="package://stikklar_description/meshes/F1.stl" scale="1 1 1"/>
      </geometry>
      <material name="grey60">
        <color rgba="0.6 0.6 0.6 1.0"/>
      </material>
    </visual>
    <collision>
      <origin rpy="-0.7853981634 0 0" xyz="-0.1649"/>
      <geometry>
        <box size="0.02 0.02 0.1"/>
      </geometry>
    </collision>
    <visual>
      <origin rpy="-0.7853981634 0 0" xyz="-0.1649"/>
      <geometry>
        <box size="0.02 0.02 0.1"/>
      </geometry>
      <material name="grey50">
        <color rgba="0.5 0.5 0.5 1.0"/>
      </material>
    </visual>
    <collision>
      <origin rpy="-0.7853981634 0 0" xyz="-0.10214"/>
      <geometry>
        <box size="0.02 0.02 0.04"/>
      </geometry>
    </collision>
    <visual>
      <origin rpy="-0.7853981634 0 0" xyz="-0.10214"/>
      <geometry>
        <box size="0.02 0.02 0.04"/>
      </geometry>
      <material name="grey50">
        <color rgba="0.5 0.5 0.5 1.0"/>
      </material>
    </visual>
    <collision>
      <origin rpy="0 -0.7853981634 1.57079632679" xyz="-0.19544"/>
      <geometry>
        <box size="0.028 0.0485 0.008"/>
      </geometry>
    </collision>
    <visual>
      <origin rpy="0 -0.7853981634 1.57079632679" xyz="-0.19544"/>
      <material name="grey60">
        <color rgba="0.6 0.6 0.6 1.0"/>
      </material>
      <geometry>
        <mesh filename="package://stikklar_description/meshes/F3.stl" scale="0.001 0.001 0.001"/>
      </geometry>
    </visual>
    <visual>
      <origin rpy="0.7853981634" xyz="-0.2272"/>
      <geometry>
        <mesh filename="package://stikklar_description/meshes/ax12.stl" scale="0.001 0.001 0.001"/>
      </geometry>
      <material name="black">
        <color rgba="0.2 0.2 0.2 1.0"/>
      </material>
    </visual>
    <collision>
      <origin rpy="0 0 0" xyz="-0.2272"/>
      <geometry>
        <box size="0.032 0.040 0.0501"/>
      </geometry>
    </collision>
  </link>
  <joint name="lf_tibia_bone_joint" type="revolute">
    <origin rpy="0 0 0" xyz="0 0 -0.082"/>
    <axis xyz="1 0 0"/>
    <limit effort="30" lower="-2.443" upper="2.443" velocity="100"/>
    <parent link="lf_femur_bone_link"/>
    <child link="lf_tibia_bone_link"/>
  </joint>
  <link name="lf_wheel_link">
    <visual>
      <origin rpy="0 0 0" xyz="0 0 0"/>
      <geometry>
        <cylinder length="0.005" radius="0.026"/>
      </geometry>
      <material name="grey30">
        <color rgba="0.3 0.3 0.3 1.0"/>
      </material>
    </visual>
  </link>
  <joint name="lf_wheel_joint" type="continuous">
    <parent link="lf_tibia_bone_link"/>
    <child link="lf_wheel_link"/>
    <origin rpy="0 1.57079632679 0" xyz="0 -0.05 -0.153"/>
    <axis rpy="0 0 0" xyz="0 0 1"/>
  </joint>
  <!-- x=red y=green z=blue -->
  <link name="lr_shoulder_link">
    <inertial>
      <mass value="0.00001"/>
      <origin xyz="0 0 0"/>
      <inertia ixx="1.0" ixy="0.0" ixz="0.0" iyy="1.0" iyz="0.0" izz="1.0"/>
    </inertial>
    <collision>
      <origin rpy="0 0 0" xyz="0 0 0"/>
      <geometry>
        <box size="0.028 0.0485 0.065"/>
      </geometry>
    </collision>
    <visual>
      <origin rpy="0 0 0" xyz="0 0 0"/>
      <!-- <material name="green"/> -->
      <material name="grey60">
        <color rgba="0.6 0.6 0.6 1.0"/>
      </material>
      <geometry>
        <mesh filename="package://stikklar_description/meshes/F4.stl" scale="0.001 0.001 0.001"/>
      </geometry>
    </visual>
  </link>
  <joint name="lr_shoulder_joint" type="fixed">
    <origin rpy="1.57079632679 0 2.35619449019" xyz="-0.1 -0.1 0"/>
    <parent link="base_link"/>
    <child link="lr_shoulder_link"/>
  </joint>
  <link name="lr_coxa_bone_link">
    <inertial>
      <mass value="0.00001"/>
      <origin xyz="0 0 0"/>
      <inertia ixx="1.0" ixy="0.0" ixz="0.0" iyy="1.0" iyz="0.0" izz="1.0"/>
    </inertial>
    <visual>
      <origin rpy="0 0 3.14159265359" xyz="0 0 0"/>
      <geometry>
        <mesh filename="package://stikklar_description/meshes/ax12.stl" scale="0.001 0.001 0.001"/>
      </geometry>
      <material name="black">
        <color rgba="0.2 0.2 0.2 1.0"/>
      </material>
    </visual>
    <collision>
      <origin rpy="0 0 0" xyz="0 0 0"/>
      <geometry>
        <box size="0.032 0.040 0.0501"/>
      </geometry>
    </collision>
    <collision>
      <origin rpy="0 3.14159265359 0 " xyz="0 0 -0.0415"/>
      <geometry>
        <box size="0.028 0.0485 0.008"/>
      </geometry>
    </collision>
    <visual>
      <origin rpy="0 3.14159265359 0 " xyz="0 0 -0.0415"/>
      <material name="grey60">
        <color rgba="0.6 0.6 0.6 1.0"/>
      </material>
      <geometry>
        <mesh filename="package://stikklar_description/meshes/F3.stl" scale="0.001 0.001 0.001"/>
      </geometry>
    </visual>
    <collision>
      <origin rpy="0 0 1.57079632679 " xyz="0 0 -0.068"/>
      <geometry>
        <box size="0.025 0.0485 0.0375"/>
      </geometry>
    </collision>
    <visual>
      <origin rpy="0 0 1.57079632679 " xyz="0 0 -0.068"/>
      <geometry>
        <mesh filename="package://stikklar_description/meshes/F2.stl" scale="0.001 0.001 0.001"/>
      </geometry>
      <material name="grey60">
        <color rgba="0.6 0.6 0.6 1.0"/>
      </material>
    </visual>
  </link>
  <joint name="lr_coxa_bone_joint" type="revolute">
    <origin rpy="0 0 0" xyz="0 0 0"/>
    <axis xyz="0 1 0"/>
    <limit effort="30" lower="-2.31119772041" upper="2.29074464324" velocity="100"/>
    <parent link="lr_shoulder_link"/>
    <child link="lr_coxa_bone_link"/>
  </joint>
  <link name="lr_femur_bone_link">
    <inertial>
      <mass value="0.00001"/>
      <origin xyz="0 0 0"/>
      <inertia ixx="1.0" ixy="0.0" ixz="0.0" iyy="1.0" iyz="0.0" izz="1.0"/>
    </inertial>
    <visual>
      <origin rpy="0 0 1.57079632679" xyz="0 0 0"/>
      <geometry>
        <mesh filename="package://stikklar_description/meshes/ax12.stl" scale="0.001 0.001 0.001"/>
      </geometry>
      <material name="black">
        <color rgba="0.2 0.2 0.2 1.0"/>
      </material>
    </visual>
    <collision>
      <origin rpy="0 0 0" xyz="0 0 0"/>
      <geometry>
        <box size="0.032 0.040 0.0501"/>
      </geometry>
    </collision>
    <collision>
      <origin rpy="0 3.14159265359 0" xyz="0 0 -0.0415"/>
      <geometry>
        <box size="0.028 0.0485 0.008"/>
      </geometry>
    </collision>
    <visual>
      <origin rpy="0 3.14159265359 0" xyz="0 0 -0.0415"/>
      <material name="grey60">
        <color rgba="0.6 0.6 0.6 1.0"/>
      </material>
      <geometry>
        <mesh filename="package://stikklar_description/meshes/F3.stl" scale="0.001 0.001 0.001"/>
      </geometry>
    </visual>
    <collision>
      <origin rpy="0 0 0" xyz="0.008 0 -0.0415"/>
      <geometry>
        <box size="0.028 0.0485 0.008"/>
      </geometry>
    </collision>
    <visual>
      <origin rpy="0 0 0" xyz="0.008 0 -0.0415"/>
      <material name="grey60">
        <color rgba="0.6 0.6 0.6 1.0"/>
      </material>
      <geometry>
        <mesh filename="package://stikklar_description/meshes/F3.stl" scale="0.001 0.001 0.001"/>
      </geometry>
    </visual>
    <visual>
      <origin rpy="3.14159265359 0 -1.57079632679" xyz="0.008 0 -0.082"/>
      <geometry>
        <mesh filename="package://stikklar_description/meshes/ax12.stl" scale="0.001 0.001 0.001"/>
      </geometry>
      <material name="black">
        <color rgba="0.2 0.2 0.2 1.0"/>
      </material>
    </visual>
    <collision>
      <origin rpy="0 0 0" xyz="0.008 0 -0.082"/>
      <geometry>
        <box size="0.032 0.040 0.0501"/>
      </geometry>
    </collision>
  </link>
  <joint name="lr_femur_bone_joint" type="revolute">
    <origin rpy="0 0 0" xyz="0 0 -0.068"/>
    <axis xyz="1 0 0"/>
    <limit effort="30" lower="-1.78964425253" upper="1.72828502102" velocity="100"/>
    <parent link="lr_coxa_bone_link"/>
    <child link="lr_femur_bone_link"/>
  </joint>
  <link name="lr_tibia_bone_link">
    <inertial>
      <mass value="0.00001"/>
      <origin xyz="0 0 0"/>
      <inertia ixx="1.0" ixy="0.0" ixz="0.0" iyy="1.0" iyz="0.0" izz="1.0"/>
    </inertial>
    <collision>
      <origin rpy="0 3.14159265359 1.57079632679" xyz="0.008 0 0"/>
      <geometry>
        <box size="0.028 0.0485 0.065"/>
      </geometry>
    </collision>
    <visual>
      <origin rpy="0 3.14159265359 1.57079632679" xyz="0.008 0 0"/>
      <!-- <material name="green"/> -->
      <material name="grey60">
        <color rgba="0.6 0.6 0.6 1.0"/>
      </material>
      <geometry>
        <mesh filename="package://stikklar_description/meshes/F4.stl" scale="0.001 0.001 0.001"/>
      </geometry>
    </visual>
    <collision>
      <origin rpy="-1.57079632679 0 1.57079632679" xyz="-0.0825"/>
      <geometry>
        <box size="0.04 0.028 0.046"/>
      </geometry>
    </collision>
    <visual>
      <origin rpy="-1.57079632679 0 1.57079632679" xyz="-0.0825"/>
      <geometry>
        <mesh filename="package://stikklar_description/meshes/F1.stl" scale="1 1 1"/>
      </geometry>
      <material name="grey60">
        <color rgba="0.6 0.6 0.6 1.0"/>
      </material>
    </visual>
    <collision>
      <origin rpy="-0.7853981634 0 0" xyz="-0.1289"/>
      <geometry>
        <box size="0.02 0.02 0.1"/>
      </geometry>
    </collision>
    <visual>
      <origin rpy="-0.7853981634 0 0" xyz="-0.1289"/>
      <geometry>
        <box size="0.02 0.02 0.1"/>
      </geometry>
      <material name="grey50">
        <color rgba="0.5 0.5 0.5 1.0"/>
      </material>
    </visual>
    <collision>
      <origin rpy="-0.7853981634 0 0" xyz="-0.10714"/>
      <geometry>
        <box size="0.02 0.02 0.04"/>
      </geometry>
    </collision>
    <visual>
      <origin rpy="-0.7853981634 0 0" xyz="-0.10714"/>
      <geometry>
        <box size="0.02 0.02 0.04"/>
      </geometry>
      <material name="grey50">
        <color rgba="0.5 0.5 0.5 1.0"/>
      </material>
    </visual>
    <collision>
      <origin rpy="0 -0.7853981634 1.57079632679" xyz="-0.14844"/>
      <geometry>
        <box size="0.028 0.0485 0.008"/>
      </geometry>
    </collision>
    <visual>
      <origin rpy="0 -0.7853981634 1.57079632679" xyz="-0.14844"/>
      <material name="grey60">
        <color rgba="0.6 0.6 0.6 1.0"/>
      </material>
      <geometry>
        <mesh filename="package://stikklar_description/meshes/F3.stl" scale="0.001 0.001 0.001"/>
      </geometry>
    </visual>
    <visual>
      <origin rpy="0.7853981634" xyz="-0.1802"/>
      <geometry>
        <mesh filename="package://stikklar_description/meshes/ax12.stl" scale="0.001 0.001 0.001"/>
      </geometry>
      <material name="black">
        <color rgba="0.2 0.2 0.2 1.0"/>
      </material>
    </visual>
    <collision>
      <origin rpy="0 0 0" xyz="-0.1802"/>
      <geometry>
        <box size="0.032 0.040 0.0501"/>
      </geometry>
    </collision>
  </link>
  <joint name="lr_tibia_bone_joint" type="revolute">
    <origin rpy="0 0 0" xyz="0 0 -0.082"/>
    <axis xyz="1 0 0"/>
    <limit effort="30" lower="-2.443" upper="2.443" velocity="100"/>
    <parent link="lr_femur_bone_link"/>
    <child link="lr_tibia_bone_link"/>
  </joint>
  <link name="lr_wheel_link">
    <visual>
      <origin rpy="0 0 0" xyz="0 0 0"/>
      <geometry>
        <cylinder length="0.005" radius="0.026"/>
      </geometry>
      <material name="grey30">
        <color rgba="0.3 0.3 0.3 1.0"/>
      </material>
    </visual>
  </link>
  <joint name="lr_wheel_joint" type="continuous">
    <parent link="lr_tibia_bone_link"/>
    <child link="lr_wheel_link"/>
    <origin rpy="0 1.57079632679 0" xyz="0 -0.05 -0.153"/>
    <axis rpy="0 0 0" xyz="0 0 1"/>
  </joint>
  <!-- x=red y=green z=blue -->
  <link name="rr_shoulder_link">
    <inertial>
      <mass value="0.00001"/>
      <origin xyz="0 0 0"/>
      <inertia ixx="1.0" ixy="0.0" ixz="0.0" iyy="1.0" iyz="0.0" izz="1.0"/>
    </inertial>
    <collision>
      <origin rpy="0 0 0" xyz="0 0 0"/>
      <geometry>
        <box size="0.028 0.0485 0.065"/>
      </geometry>
    </collision>
    <visual>
      <origin rpy="0 0 0" xyz="0 0 0"/>
      <!-- <material name="green"/> -->
      <material name="grey60">
        <color rgba="0.6 0.6 0.6 1.0"/>
      </material>
      <geometry>
        <mesh filename="package://stikklar_description/meshes/F4.stl" scale="0.001 0.001 0.001"/>
      </geometry>
    </visual>
  </link>
  <joint name="rr_shoulder_joint" type="fixed">
    <origin rpy="1.57079632679 0 -2.35619449019" xyz="0.1 -0.1 0"/>
    <parent link="base_link"/>
    <child link="rr_shoulder_link"/>
  </joint>
  <link name="rr_coxa_bone_link">
    <inertial>
      <mass value="0.00001"/>
      <origin xyz="0 0 0"/>
      <inertia ixx="1.0" ixy="0.0" ixz="0.0" iyy="1.0" iyz="0.0" izz="1.0"/>
    </inertial>
    <visual>
      <origin rpy="0 0 3.14159265359" xyz="0 0 0"/>
      <geometry>
        <mesh filename="package://stikklar_description/meshes/ax12.stl" scale="0.001 0.001 0.001"/>
      </geometry>
      <material name="black">
        <color rgba="0.2 0.2 0.2 1.0"/>
      </material>
    </visual>
    <collision>
      <origin rpy="0 0 0" xyz="0 0 0"/>
      <geometry>
        <box size="0.032 0.040 0.0501"/>
      </geometry>
    </collision>
    <collision>
      <origin rpy="0 3.14159265359 0 " xyz="0 0 -0.0415"/>
      <geometry>
        <box size="0.028 0.0485 0.008"/>
      </geometry>
    </collision>
    <visual>
      <origin rpy="0 3.14159265359 0 " xyz="0 0 -0.0415"/>
      <material name="grey60">
        <color rgba="0.6 0.6 0.6 1.0"/>
      </material>
      <geometry>
        <mesh filename="package://stikklar_description/meshes/F3.stl" scale="0.001 0.001 0.001"/>
      </geometry>
    </visual>
    <collision>
      <origin rpy="0 0 1.57079632679 " xyz="0 0 -0.068"/>
      <geometry>
        <box size="0.025 0.0485 0.0375"/>
      </geometry>
    </collision>
    <visual>
      <origin rpy="0 0 1.57079632679 " xyz="0 0 -0.068"/>
      <geometry>
        <mesh filename="package://stikklar_description/meshes/F2.stl" scale="0.001 0.001 0.001"/>
      </geometry>
      <material name="grey60">
        <color rgba="0.6 0.6 0.6 1.0"/>
      </material>
    </visual>
  </link>
  <joint name="rr_coxa_bone_joint" type="revolute">
    <origin rpy="0 0 0" xyz="0 0 0"/>
    <axis xyz="0 1 0"/>
    <limit effort="30" lower="-2.31119772041" upper="2.29074464324" velocity="100"/>
    <parent link="rr_shoulder_link"/>
    <child link="rr_coxa_bone_link"/>
  </joint>
  <link name="rr_femur_bone_link">
    <inertial>
      <mass value="0.00001"/>
      <origin xyz="0 0 0"/>
      <inertia ixx="1.0" ixy="0.0" ixz="0.0" iyy="1.0" iyz="0.0" izz="1.0"/>
    </inertial>
    <visual>
      <origin rpy="0 0 1.57079632679" xyz="0 0 0"/>
      <geometry>
        <mesh filename="package://stikklar_description/meshes/ax12.stl" scale="0.001 0.001 0.001"/>
      </geometry>
      <material name="black">
        <color rgba="0.2 0.2 0.2 1.0"/>
      </material>
    </visual>
    <collision>
      <origin rpy="0 0 0" xyz="0 0 0"/>
      <geometry>
        <box size="0.032 0.040 0.0501"/>
      </geometry>
    </collision>
    <collision>
      <origin rpy="0 3.14159265359 0" xyz="0 0 -0.0415"/>
      <geometry>
        <box size="0.028 0.0485 0.008"/>
      </geometry>
    </collision>
    <visual>
      <origin rpy="0 3.14159265359 0" xyz="0 0 -0.0415"/>
      <material name="grey60">
        <color rgba="0.6 0.6 0.6 1.0"/>
      </material>
      <geometry>
        <mesh filename="package://stikklar_description/meshes/F3.stl" scale="0.001 0.001 0.001"/>
      </geometry>
    </visual>
    <collision>
      <origin rpy="0 0 0" xyz="-0.008 0 -0.0415"/>
      <geometry>
        <box size="0.028 0.0485 0.008"/>
      </geometry>
    </collision>
    <visual>
      <origin rpy="0 0 0" xyz="-0.008 0 -0.0415"/>
      <material name="grey60">
        <color rgba="0.6 0.6 0.6 1.0"/>
      </material>
      <geometry>
        <mesh filename="package://stikklar_description/meshes/F3.stl" scale="0.001 0.001 0.001"/>
      </geometry>
    </visual>
    <visual>
      <origin rpy="3.14159265359 0 -1.57079632679" xyz="-0.008 0 -0.082"/>
      <geometry>
        <mesh filename="package://stikklar_description/meshes/ax12.stl" scale="0.001 0.001 0.001"/>
      </geometry>
      <material name="black">
        <color rgba="0.2 0.2 0.2 1.0"/>
      </material>
    </visual>
    <collision>
      <origin rpy="0 0 0" xyz="-0.008 0 -0.082"/>
      <geometry>
        <box size="0.032 0.040 0.0501"/>
      </geometry>
    </collision>
  </link>
  <joint name="rr_femur_bone_joint" type="revolute">
    <origin rpy="0 0 0" xyz="0 0 -0.068"/>
    <axis xyz="1 0 0"/>
    <limit effort="30" lower="-1.78964425253" upper="1.72828502102" velocity="100"/>
    <parent link="rr_coxa_bone_link"/>
    <child link="rr_femur_bone_link"/>
  </joint>
  <link name="rr_tibia_bone_link">
    <inertial>
      <mass value="0.00001"/>
      <origin xyz="0 0 0"/>
      <inertia ixx="1.0" ixy="0.0" ixz="0.0" iyy="1.0" iyz="0.0" izz="1.0"/>
    </inertial>
    <collision>
      <origin rpy="0 3.14159265359 1.57079632679" xyz="-0.008 0 0"/>
      <geometry>
        <box size="0.028 0.0485 0.065"/>
      </geometry>
    </collision>
    <visual>
      <origin rpy="0 3.14159265359 1.57079632679" xyz="-0.008 0 0"/>
      <!-- <material name="green"/> -->
      <material name="grey60">
        <color rgba="0.6 0.6 0.6 1.0"/>
      </material>
      <geometry>
        <mesh filename="package://stikklar_description/meshes/F4.stl" scale="0.001 0.001 0.001"/>
      </geometry>
    </visual>
    <collision>
      <origin rpy="-1.57079632679 0 1.57079632679" xyz="-0.0985"/>
      <geometry>
        <box size="0.04 0.028 0.046"/>
      </geometry>
    </collision>
    <visual>
      <origin rpy="-1.57079632679 0 1.57079632679" xyz="-0.0985"/>
      <geometry>
        <mesh filename="package://stikklar_description/meshes/F1.stl" scale="1 1 1"/>
      </geometry>
      <material name="grey60">
        <color rgba="0.6 0.6 0.6 1.0"/>
      </material>
    </visual>
    <collision>
      <origin rpy="-0.7853981634 0 0" xyz="-0.1649"/>
      <geometry>
        <box size="0.02 0.02 0.1"/>
      </geometry>
    </collision>
    <visual>
      <origin rpy="-0.7853981634 0 0" xyz="-0.1649"/>
      <geometry>
        <box size="0.02 0.02 0.1"/>
      </geometry>
      <material name="grey50">
        <color rgba="0.5 0.5 0.5 1.0"/>
      </material>
    </visual>
    <collision>
      <origin rpy="-0.7853981634 0 0" xyz="-0.10214"/>
      <geometry>
        <box size="0.02 0.02 0.04"/>
      </geometry>
    </collision>
    <visual>
      <origin rpy="-0.7853981634 0 0" xyz="-0.10214"/>
      <geometry>
        <box size="0.02 0.02 0.04"/>
      </geometry>
      <material name="grey50">
        <color rgba="0.5 0.5 0.5 1.0"/>
      </material>
    </visual>
    <collision>
      <origin rpy="0 -0.7853981634 1.57079632679" xyz="-0.19544"/>
      <geometry>
        <box size="0.028 0.0485 0.008"/>
      </geometry>
    </collision>
    <visual>
      <origin rpy="0 -0.7853981634 1.57079632679" xyz="-0.19544"/>
      <material name="grey60">
        <color rgba="0.6 0.6 0.6 1.0"/>
      </material>
      <geometry>
        <mesh filename="package://stikklar_description/meshes/F3.stl" scale="0.001 0.001 0.001"/>
      </geometry>
    </visual>
    <visual>
      <origin rpy="0.7853981634" xyz="-0.2272"/>
      <geometry>
        <mesh filename="package://stikklar_description/meshes/ax12.stl" scale="0.001 0.001 0.001"/>
      </geometry>
      <material name="black">
        <color rgba="0.2 0.2 0.2 1.0"/>
      </material>
    </visual>
    <collision>
      <origin rpy="0 0 0" xyz="-0.2272"/>
      <geometry>
        <box size="0.032 0.040 0.0501"/>
      </geometry>
    </collision>
  </link>
  <joint name="rr_tibia_bone_joint" type="revolute">
    <origin rpy="0 0 0" xyz="0 0 -0.082"/>
    <axis xyz="1 0 0"/>
    <limit effort="30" lower="-2.443" upper="2.443" velocity="100"/>
    <parent link="rr_femur_bone_link"/>
    <child link="rr_tibia_bone_link"/>
  </joint>
  <link name="rr_wheel_link">
    <visual>
      <origin rpy="0 0 0" xyz="0 0 0"/>
      <geometry>
        <cylinder length="0.005" radius="0.026"/>
      </geometry>
      <material name="grey30">
        <color rgba="0.3 0.3 0.3 1.0"/>
      </material>
    </visual>
  </link>
  <joint name="rr_wheel_joint" type="continuous">
    <parent link="rr_tibia_bone_link"/>
    <child link="rr_wheel_link"/>
    <origin rpy="0 1.57079632679 0" xyz="0 -0.05 -0.153"/>
    <axis rpy="0 0 0" xyz="0 0 1"/>
  </joint>
  <!-- x=red y=green z=blue -->
  <link name="rf_shoulder_link">
    <inertial>
      <mass value="0.00001"/>
      <origin xyz="0 0 0"/>
      <inertia ixx="1.0" ixy="0.0" ixz="0.0" iyy="1.0" iyz="0.0" izz="1.0"/>
    </inertial>
    <collision>
      <origin rpy="0 0 0" xyz="0 0 0"/>
      <geometry>
        <box size="0.028 0.0485 0.065"/>
      </geometry>
    </collision>
    <visual>
      <origin rpy="0 0 0" xyz="0 0 0"/>
      <!-- <material name="green"/> -->
      <material name="grey60">
        <color rgba="0.6 0.6 0.6 1.0"/>
      </material>
      <geometry>
        <mesh filename="package://stikklar_description/meshes/F4.stl" scale="0.001 0.001 0.001"/>
      </geometry>
    </visual>
  </link>
  <joint name="rf_shoulder_joint" type="fixed">
    <origin rpy="1.57079632679 0 -0.7853981634" xyz="0.1 0.1 0"/>
    <parent link="base_link"/>
    <child link="rf_shoulder_link"/>
  </joint>
  <link name="rf_coxa_bone_link">
    <inertial>
      <mass value="0.00001"/>
      <origin xyz="0 0 0"/>
      <inertia ixx="1.0" ixy="0.0" ixz="0.0" iyy="1.0" iyz="0.0" izz="1.0"/>
    </inertial>
    <visual>
      <origin rpy="0 0 3.14159265359" xyz="0 0 0"/>
      <geometry>
        <mesh filename="package://stikklar_description/meshes/ax12.stl" scale="0.001 0.001 0.001"/>
      </geometry>
      <material name="black">
        <color rgba="0.2 0.2 0.2 1.0"/>
      </material>
    </visual>
    <collision>
      <origin rpy="0 0 0" xyz="0 0 0"/>
      <geometry>
        <box size="0.032 0.040 0.0501"/>
      </geometry>
    </collision>
    <collision>
      <origin rpy="0 3.14159265359 0 " xyz="0 0 -0.0415"/>
      <geometry>
        <box size="0.028 0.0485 0.008"/>
      </geometry>
    </collision>
    <visual>
      <origin rpy="0 3.14159265359 0 " xyz="0 0 -0.0415"/>
      <material name="grey60">
        <color rgba="0.6 0.6 0.6 1.0"/>
      </material>
      <geometry>
        <mesh filename="package://stikklar_description/meshes/F3.stl" scale="0.001 0.001 0.001"/>
      </geometry>
    </visual>
    <collision>
      <origin rpy="0 0 1.57079632679 " xyz="0 0 -0.068"/>
      <geometry>
        <box size="0.025 0.0485 0.0375"/>
      </geometry>
    </collision>
    <visual>
      <origin rpy="0 0 1.57079632679 " xyz="0 0 -0.068"/>
      <geometry>
        <mesh filename="package://stikklar_description/meshes/F2.stl" scale="0.001 0.001 0.001"/>
      </geometry>
      <material name="grey60">
        <color rgba="0.6 0.6 0.6 1.0"/>
      </material>
    </visual>
  </link>
  <joint name="rf_coxa_bone_joint" type="revolute">
    <origin rpy="0 0 0" xyz="0 0 0"/>
    <axis xyz="0 1 0"/>
    <limit effort="30" lower="-2.31119772041" upper="2.29074464324" velocity="100"/>
    <parent link="rf_shoulder_link"/>
    <child link="rf_coxa_bone_link"/>
  </joint>
  <link name="rf_femur_bone_link">
    <inertial>
      <mass value="0.00001"/>
      <origin xyz="0 0 0"/>
      <inertia ixx="1.0" ixy="0.0" ixz="0.0" iyy="1.0" iyz="0.0" izz="1.0"/>
    </inertial>
    <visual>
      <origin rpy="0 0 1.57079632679" xyz="0 0 0"/>
      <geometry>
        <mesh filename="package://stikklar_description/meshes/ax12.stl" scale="0.001 0.001 0.001"/>
      </geometry>
      <material name="black">
        <color rgba="0.2 0.2 0.2 1.0"/>
      </material>
    </visual>
    <collision>
      <origin rpy="0 0 0" xyz="0 0 0"/>
      <geometry>
        <box size="0.032 0.040 0.0501"/>
      </geometry>
    </collision>
    <collision>
      <origin rpy="0 3.14159265359 0" xyz="0 0 -0.0415"/>
      <geometry>
        <box size="0.028 0.0485 0.008"/>
      </geometry>
    </collision>
    <visual>
      <origin rpy="0 3.14159265359 0" xyz="0 0 -0.0415"/>
      <material name="grey60">
        <color rgba="0.6 0.6 0.6 1.0"/>
      </material>
      <geometry>
        <mesh filename="package://stikklar_description/meshes/F3.stl" scale="0.001 0.001 0.001"/>
      </geometry>
    </visual>
    <collision>
      <origin rpy="0 0 0" xyz="0.008 0 -0.0415"/>
      <geometry>
        <box size="0.028 0.0485 0.008"/>
      </geometry>
    </collision>
    <visual>
      <origin rpy="0 0 0" xyz="0.008 0 -0.0415"/>
      <material name="grey60">
        <color rgba="0.6 0.6 0.6 1.0"/>
      </material>
      <geometry>
        <mesh filename="package://stikklar_description/meshes/F3.stl" scale="0.001 0.001 0.001"/>
      </geometry>
    </visual>
    <visual>
      <origin rpy="3.14159265359 0 -1.57079632679" xyz="0.008 0 -0.082"/>
      <geometry>
        <mesh filename="package://stikklar_description/meshes/ax12.stl" scale="0.001 0.001 0.001"/>
      </geometry>
      <material name="black">
        <color rgba="0.2 0.2 0.2 1.0"/>
      </material>
    </visual>
    <collision>
      <origin rpy="0 0 0" xyz="0.008 0 -0.082"/>
      <geometry>
        <box size="0.032 0.040 0.0501"/>
      </geometry>
    </collision>
  </link>
  <joint name="rf_femur_bone_joint" type="revolute">
    <origin rpy="0 0 0" xyz="0 0 -0.068"/>
    <axis xyz="1 0 0"/>
    <limit effort="30" lower="-1.78964425253" upper="1.72828502102" velocity="100"/>
    <parent link="rf_coxa_bone_link"/>
    <child link="rf_femur_bone_link"/>
  </joint>
  <link name="rf_tibia_bone_link">
    <inertial>
      <mass value="0.00001"/>
      <origin xyz="0 0 0"/>
      <inertia ixx="1.0" ixy="0.0" ixz="0.0" iyy="1.0" iyz="0.0" izz="1.0"/>
    </inertial>
    <collision>
      <origin rpy="0 3.14159265359 1.57079632679" xyz="0.008 0 0"/>
      <geometry>
        <box size="0.028 0.0485 0.065"/>
      </geometry>
    </collision>
    <visual>
      <origin rpy="0 3.14159265359 1.57079632679" xyz="0.008 0 0"/>
      <!-- <material name="green"/> -->
      <material name="grey60">
        <color rgba="0.6 0.6 0.6 1.0"/>
      </material>
      <geometry>
        <mesh filename="package://stikklar_description/meshes/F4.stl" scale="0.001 0.001 0.001"/>
      </geometry>
    </visual>
    <collision>
      <origin rpy="-1.57079632679 0 1.57079632679" xyz="-0.0825"/>
      <geometry>
        <box size="0.04 0.028 0.046"/>
      </geometry>
    </collision>
    <visual>
      <origin rpy="-1.57079632679 0 1.57079632679" xyz="-0.0825"/>
      <geometry>
        <mesh filename="package://stikklar_description/meshes/F1.stl" scale="1 1 1"/>
      </geometry>
      <material name="grey60">
        <color rgba="0.6 0.6 0.6 1.0"/>
      </material>
    </visual>
    <collision>
      <origin rpy="-0.7853981634 0 0" xyz="-0.1289"/>
      <geometry>
        <box size="0.02 0.02 0.1"/>
      </geometry>
    </collision>
    <visual>
      <origin rpy="-0.7853981634 0 0" xyz="-0.1289"/>
      <geometry>
        <box size="0.02 0.02 0.1"/>
      </geometry>
      <material name="grey50">
        <color rgba="0.5 0.5 0.5 1.0"/>
      </material>
    </visual>
    <collision>
      <origin rpy="-0.7853981634 0 0" xyz="-0.10714"/>
      <geometry>
        <box size="0.02 0.02 0.04"/>
      </geometry>
    </collision>
    <visual>
      <origin rpy="-0.7853981634 0 0" xyz="-0.10714"/>
      <geometry>
        <box size="0.02 0.02 0.04"/>
      </geometry>
      <material name="grey50">
        <color rgba="0.5 0.5 0.5 1.0"/>
      </material>
    </visual>
    <collision>
      <origin rpy="0 -0.7853981634 1.57079632679" xyz="-0.14844"/>
      <geometry>
        <box size="0.028 0.0485 0.008"/>
      </geometry>
    </collision>
    <visual>
      <origin rpy="0 -0.7853981634 1.57079632679" xyz="-0.14844"/>
      <material name="grey60">
        <color rgba="0.6 0.6 0.6 1.0"/>
      </material>
      <geometry>
        <mesh filename="package://stikklar_description/meshes/F3.stl" scale="0.001 0.001 0.001"/>
      </geometry>
    </visual>
    <visual>
      <origin rpy="0.7853981634" xyz="-0.1802"/>
      <geometry>
        <mesh filename="package://stikklar_description/meshes/ax12.stl" scale="0.001 0.001 0.001"/>
      </geometry>
      <material name="black">
        <color rgba="0.2 0.2 0.2 1.0"/>
      </material>
    </visual>
    <collision>
      <origin rpy="0 0 0" xyz="-0.1802"/>
      <geometry>
        <box size="0.032 0.040 0.0501"/>
      </geometry>
    </collision>
  </link>
  <joint name="rf_tibia_bone_joint" type="revolute">
    <origin rpy="0 0 0" xyz="0 0 -0.082"/>
    <axis xyz="1 0 0"/>
    <limit effort="30" lower="-2.443" upper="2.443" velocity="100"/>
    <parent link="rf_femur_bone_link"/>
    <child link="rf_tibia_bone_link"/>
  </joint>
  <link name="rf_wheel_link">
    <visual>
      <origin rpy="0 0 0" xyz="0 0 0"/>
      <geometry>
        <cylinder length="0.005" radius="0.026"/>
      </geometry>
      <material name="grey30">
        <color rgba="0.3 0.3 0.3 1.0"/>
      </material>
    </visual>
  </link>
  <joint name="rf_wheel_joint" type="continuous">
    <parent link="rf_tibia_bone_link"/>
    <child link="rf_wheel_link"/>
    <origin rpy="0 1.57079632679 0" xyz="0 -0.05 -0.153"/>
    <axis rpy="0 0 0" xyz="0 0 1"/>
  </joint>
  <link name="neck_base_link">
    <inertial>
      <mass value="0.00001"/>
      <origin xyz="0 0 0"/>
      <inertia ixx="1.0" ixy="0.0" ixz="0.0" iyy="1.0" iyz="0.0" izz="1.0"/>
    </inertial>
    <visual>
      <origin rpy="0 0 0" xyz="0 -0.023 0"/>
      <geometry>
        <mesh filename="package://stikklar_description/meshes/ax12.stl" scale="0.001 0.001 0.001"/>
      </geometry>
      <material name="black">
        <color rgba="0.2 0.2 0.2 1.0"/>
      </material>
    </visual>
    <collision>
      <origin rpy="0 0 0" xyz="0 -0.023 0"/>
      <geometry>
        <box size="0.032 0.040 0.0501"/>
      </geometry>
    </collision>
  </link>
  <joint name="neck_base_joint" type="fixed">
    <origin rpy="1.57079632679 0 0" xyz="0 0 0.0665"/>
    <parent link="base_link"/>
    <child link="neck_base_link"/>
  </joint>
  <link name="neck_pan_link">
    <inertial>
      <mass value="0.00001"/>
      <origin xyz="0 0 0"/>
      <inertia ixx="1.0" ixy="0.0" ixz="0.0" iyy="1.0" iyz="0.0" izz="1.0"/>
    </inertial>
    <collision>
      <origin rpy="1.57079632679 1.57079632679 0" xyz="0 0 0"/>
      <geometry>
        <box size="0.028 0.0485 0.008"/>
      </geometry>
    </collision>
    <visual>
      <origin rpy="1.57079632679 1.57079632679 0" xyz="0 0 0"/>
      <material name="grey60">
        <color rgba="0.6 0.6 0.6 1.0"/>
      </material>
      <geometry>
        <mesh filename="package://stikklar_description/meshes/F3.stl" scale="0.001 0.001 0.001"/>
      </geometry>
    </visual>
    <visual>
      <origin rpy="-1.57079632679 -1.57079632679 0" xyz="0 0.04 0"/>
      <geometry>
        <mesh filename="package://stikklar_description/meshes/ax12.stl" scale="0.001 0.001 0.001"/>
      </geometry>
      <material name="black">
        <color rgba="0.2 0.2 0.2 1.0"/>
      </material>
    </visual>
    <collision>
      <origin rpy="0 0 0" xyz="0 0.04 0"/>
      <geometry>
        <box size="0.032 0.040 0.0501"/>
      </geometry>
    </collision>
    <!--part_F2 xyz="0 0 -${L_COXA}" rpy="0 0 ${MPI2} "/-->
  </link>
  <joint name="neck_pan_joint" type="revolute">
    <origin rpy="0 0 0" xyz="0 0 0"/>
    <axis xyz="0 -1 0"/>
    <limit effort="30" lower="-2.61799" upper="2.61799" velocity="100"/>
    <parent link="neck_base_link"/>
    <child link="neck_pan_link"/>
  </joint>
  <link name="neck_tilt_link">
    <inertial>
      <mass value="0.00001"/>
      <origin xyz="0 0 0"/>
      <inertia ixx="1.0" ixy="0.0" ixz="0.0" iyy="1.0" iyz="0.0" izz="1.0"/>
    </inertial>
    <collision>
      <origin rpy="1.57079632679 1.57079632679 0" xyz="0 0 0"/>
      <geometry>
        <box size="0.025 0.0485 0.0375"/>
      </geometry>
    </collision>
    <visual>
      <origin rpy="1.57079632679 1.57079632679 0" xyz="0 0 0"/>
      <geometry>
        <mesh filename="package://stikklar_description/meshes/F2.stl" scale="0.001 0.001 0.001"/>
      </geometry>
      <material name="grey60">
        <color rgba="0.6 0.6 0.6 1.0"/>
      </material>
    </visual>
    <collision>
      <origin rpy="0 0 0" xyz="0 -0.076 0"/>
      <geometry>
        <box size="0.065 0.1 0.03"/>
      </geometry>
    </collision>
    <visual>
      <origin rpy="0 0 0" xyz="0 -0.076 0"/>
      <geometry>
        <box size="0.065 0.1 0.03"/>
      </geometry>
      <material name="grey70">
        <color rgba="0.7 0.7 0.7 1.0"/>
      </material>
    </visual>
    <visual>
      <origin rpy="0 0 0" xyz="0.013 -0.081 0.015"/>
      <geometry>
        <cylinder length="0.002" radius="0.004"/>
      </geometry>
      <material name="black">
        <color rgba="0.2 0.2 0.2 1.0"/>
      </material>
    </visual>
  </link>
  <joint name="neck_tilt_joint" type="revolute">
    <origin rpy="3.14159265359 0 0" xyz="0 0.038 0"/>
    <axis xyz="1 0 0"/>
    <limit effort="30" lower="-1.5707" upper="1.5707" velocity="100"/>
    <parent link="neck_pan_link"/>
    <child link="neck_tilt_link"/>
  </joint>
</robot>

