<?xml version="1.0" ?>
<!-- =================================================================================== -->
<!-- |    This document was autogenerated by xacro from stikklar.urdf.xacro            | -->
<!-- |    EDITING THIS FILE BY HAND IS NOT RECOMMENDED                                 | -->
<!-- =================================================================================== -->
<robot name="stikklar" xmlns:xacro="http://www.ros.org/wiki/xacro">
  <material name="black">
    <color rgba="0.2 0.2 0.2 1.0"/>
  </material>
  <material name="orange">
    <color rgba="1.0 0.55 0.0 1.0"/>
  </material>
  <material name="grey20">
    <color rgba="0.2 0.2 0.2 1.0"/>
  </material>
  <material name="grey25">
    <color rgba="0.25 0.25 0.25 1.0"/>
  </material>
  <material name="grey30">
    <color rgba="0.3 0.3 0.3 1.0"/>
  </material>
  <material name="grey40">
    <color rgba="0.4 0.4 0.4 1.0"/>
  </material>
  <material name="grey50">
    <color rgba="0.5 0.5 0.5 1.0"/>
  </material>
  <material name="grey60">
    <color rgba="0.6 0.6 0.6 1.0"/>
  </material>
  <material name="grey70">
    <color rgba="0.7 0.7 0.7 1.0"/>
  </material>
  <material name="grey75">
    <color rgba="0.75 0.75 0.75 1.0"/>
  </material>
  <material name="grey">
    <color rgba="0.5 0.5 0.5 1.0"/>
  </material>
  <material name="red">
    <color rgba="0.8 0.0 0.0 1.0"/>
  </material>
  <material name="white">
    <color rgba="1.0 1.0 1.0 1.0"/>
  </material>
  <material name="blue">
    <color rgba="0.0 0.0 0.8 1.0"/>
  </material>
  <material name="green">
    <color rgba="0.0 0.8 0.0 1.0"/>
  </material>
  <material name="lightblue">
    <color rgba="0.55 0.75 0.9 10"/>
  </material>
  <link name="base_link">
    <inertial>
      <mass value="0.00001"/>
      <origin xyz="0 0 0"/>
      <inertia ixx="1.0" ixy="0.0" ixz="0.0" iyy="1.0" iyz="0.0" izz="1.0"/>
    </inertial>
    <visual>
      <origin rpy="0 0 0" xyz="0 0 0"/>
      <geometry>
        <box size="0.14 0.14 0.055"/>
      </geometry>
      <material name="grey25"/>
    </visual>
    <collision>
      <origin rpy="0 0 0" xyz="0 0 0"/>
      <geometry>
        <box size="0.14 0.14 0.055"/>
      </geometry>
    </collision>
  </link>
  <link name="lf_shoulder_link">
    <inertial>
      <mass value="0.00001"/>
      <origin xyz="0 0 0"/>
      <inertia ixx="1.0" ixy="0.0" ixz="0.0" iyy="1.0" iyz="0.0" izz="1.0"/>
    </inertial>
    <collision>
      <origin rpy="0 0 0" xyz="0 0 0"/>
      <geometry>
        <box size="0.028 0.0485 0.065"/>
      </geometry>
    </collision>
    <visual>
      <origin rpy="0 0 0" xyz="0 0 0"/>
      <material name="grey60"/>
      <geometry>
        <mesh filename="package://stikklar_description/meshes/F4.stl" scale="0.001 0.001 0.001"/>
      </geometry>
    </visual>
  </link>
  <joint name="lf_shoulder_joint" type="fixed">
    <origin rpy="1.57079632679 0 -0.7853981634" xyz="0.1 0.1 0"/>
    <parent link="base_link"/>
    <child link="lf_shoulder_link"/>
  </joint>
  <link name="lf_coxa_bone_link">
    <inertial>
      <mass value="0.00001"/>
      <origin xyz="0 0 0"/>
      <inertia ixx="1.0" ixy="0.0" ixz="0.0" iyy="1.0" iyz="0.0" izz="1.0"/>
    </inertial>
    <visual>
      <origin rpy="0 0 3.14159265359" xyz="0 0 0"/>
      <geometry>
        <mesh filename="package://stikklar_description/meshes/ax12.stl" scale="0.001 0.001 0.001"/>
      </geometry>
      <material name="grey30"/>
    </visual>
    <collision>
      <origin rpy="0 0 0" xyz="0 0 0"/>
      <geometry>
        <box size="0.032 0.040 0.0501"/>
      </geometry>
    </collision>
    <collision>
      <origin rpy="0 3.14159265359 0 " xyz="0 0 -0.0415"/>
      <geometry>
        <box size="0.028 0.0485 0.065"/>
      </geometry>
    </collision>
    <visual>
      <origin rpy="0 3.14159265359 0 " xyz="0 0 -0.0415"/>
      <material name="green"/>
      <geometry>
        <mesh filename="package://stikklar_description/meshes/F3.stl" scale="0.001 0.001 0.001"/>
      </geometry>
    </visual>
    <collision>
      <origin rpy="0 0 1.57079632679 " xyz="0 0 -0.068"/>
      <geometry>
        <box size="0.025 0.0485 0.0375"/>
      </geometry>
    </collision>
    <visual>
      <origin rpy="0 0 1.57079632679 " xyz="0 0 -0.068"/>
      <geometry>
        <mesh filename="package://stikklar_description/meshes/F2.stl" scale="0.001 0.001 0.001"/>
      </geometry>
      <material name="grey60"/>
    </visual>
  </link>
  <joint name="lf_coxa_bone_joint" type="revolute">
    <origin rpy="0 0 0" xyz="0 0 0"/>
    <axis xyz="0 1 0"/>
    <limit effort="30" lower="-2.31119772041" upper="2.29074464324" velocity="100"/>
    <parent link="lf_shoulder_link"/>
    <child link="lf_coxa_bone_link"/>
  </joint>
  <link name="lf_femur_bone_link">
    <inertial>
      <mass value="0.00001"/>
      <origin xyz="0 0 0"/>
      <inertia ixx="1.0" ixy="0.0" ixz="0.0" iyy="1.0" iyz="0.0" izz="1.0"/>
    </inertial>
    <visual>
      <origin rpy="0 0 1.57079632679" xyz="0 0 0"/>
      <geometry>
        <mesh filename="package://stikklar_description/meshes/ax12.stl" scale="0.001 0.001 0.001"/>
      </geometry>
      <material name="grey30"/>
    </visual>
    <collision>
      <origin rpy="0 0 0" xyz="0 0 0"/>
      <geometry>
        <box size="0.032 0.040 0.0501"/>
      </geometry>
    </collision>
    <collision>
      <origin rpy="0 3.14159265359 0" xyz="0 0 -0.0415"/>
      <geometry>
        <box size="0.028 0.0485 0.065"/>
      </geometry>
    </collision>
    <visual>
      <origin rpy="0 3.14159265359 0" xyz="0 0 -0.0415"/>
      <material name="green"/>
      <geometry>
        <mesh filename="package://stikklar_description/meshes/F3.stl" scale="0.001 0.001 0.001"/>
      </geometry>
    </visual>
    <collision>
      <origin rpy="0 0 0" xyz="0.008 0 -0.0415"/>
      <geometry>
        <box size="0.028 0.0485 0.065"/>
      </geometry>
    </collision>
    <visual>
      <origin rpy="0 0 0" xyz="0.008 0 -0.0415"/>
      <material name="green"/>
      <geometry>
        <mesh filename="package://stikklar_description/meshes/F3.stl" scale="0.001 0.001 0.001"/>
      </geometry>
    </visual>
    <visual>
      <origin rpy="3.14159265359 0 -1.57079632679" xyz="0.008 0 -0.082"/>
      <geometry>
        <mesh filename="package://stikklar_description/meshes/ax12.stl" scale="0.001 0.001 0.001"/>
      </geometry>
      <material name="grey30"/>
    </visual>
    <collision>
      <origin rpy="0 0 0" xyz="0.008 0 -0.082"/>
      <geometry>
        <box size="0.032 0.040 0.0501"/>
      </geometry>
    </collision>
  </link>
  <joint name="lf_femur_bone_joint" type="revolute">
    <origin rpy="0 0 0" xyz="0 0 -0.068"/>
    <axis xyz="1 0 0"/>
    <limit effort="30" lower="-1.78964425253" upper="1.72828502102" velocity="100"/>
    <parent link="lf_coxa_bone_link"/>
    <child link="lf_femur_bone_link"/>
  </joint>
  <link name="lf_tibia_bone_link">
    <inertial>
      <mass value="0.00001"/>
      <origin xyz="0 0 0"/>
      <inertia ixx="1.0" ixy="0.0" ixz="0.0" iyy="1.0" iyz="0.0" izz="1.0"/>
    </inertial>
    <collision>
      <origin rpy="0 3.14159265359 1.57079632679" xyz="0.008 0 0"/>
      <geometry>
        <box size="0.028 0.0485 0.065"/>
      </geometry>
    </collision>
    <visual>
      <origin rpy="0 3.14159265359 1.57079632679" xyz="0.008 0 0"/>
      <material name="grey60"/>
      <geometry>
        <mesh filename="package://stikklar_description/meshes/F4.stl" scale="0.001 0.001 0.001"/>
      </geometry>
    </visual>
    <collision>
      <origin rpy="-1.57079632679 0 1.57079632679" xyz="0.008 -0.015 -0.0755"/>
      <geometry>
        <box size="0.04 0.028 0.046"/>
      </geometry>
    </collision>
    <visual>
      <origin rpy="-1.57079632679 0 1.57079632679" xyz="0.008 -0.015 -0.0755"/>
      <geometry>
        <mesh filename="package://stikklar_description/meshes/F1.stl" scale="1 1 1"/>
      </geometry>
      <material name="grey60"/>
    </visual>
    <collision>
      <origin rpy="-0.7853981634 0 0" xyz="0.018 -0.0398 -0.1073"/>
      <geometry>
        <box size="0.02 0.02 0.1"/>
      </geometry>
    </collision>
    <visual>
      <origin rpy="-0.7853981634 0 0" xyz="0.018 -0.0398 -0.1073"/>
      <geometry>
        <box size="0.02 0.02 0.1"/>
      </geometry>
      <material name="grey70"/>
    </visual>
    <collision>
      <origin rpy="-0.7853981634 0 0" xyz="-0.0025 -0.02207 -0.08257"/>
      <geometry>
        <box size="0.02 0.02 0.04"/>
      </geometry>
    </collision>
    <visual>
      <origin rpy="-0.7853981634 0 0" xyz="-0.0025 -0.02207 -0.08257"/>
      <geometry>
        <box size="0.02 0.02 0.04"/>
      </geometry>
      <material name="grey70"/>
    </visual>
    <collision>
      <origin rpy="0 -0.7853981634 1.57079632679" xyz="0.0235 -0.04865 -0.13029"/>
      <geometry>
        <box size="0.028 0.0485 0.065"/>
      </geometry>
    </collision>
    <visual>
      <origin rpy="0 -0.7853981634 1.57079632679" xyz="0.0235 -0.04865 -0.13029"/>
      <material name="green"/>
      <geometry>
        <mesh filename="package://stikklar_description/meshes/F3.stl" scale="0.001 0.001 0.001"/>
      </geometry>
    </visual>
    <visual>
      <origin rpy="3.14159265359 -0.7853981634 -1.57079632679" xyz="0.0235 -0.05078 -0.15928"/>
      <geometry>
        <mesh filename="package://stikklar_description/meshes/ax12.stl" scale="0.001 0.001 0.001"/>
      </geometry>
      <material name="grey30"/>
    </visual>
    <collision>
      <origin rpy="0 0 0" xyz="0.0235 -0.05078 -0.15928"/>
      <geometry>
        <box size="0.032 0.040 0.0501"/>
      </geometry>
    </collision>
  </link>
  <joint name="lf_tibia_bone_joint" type="revolute">
    <origin rpy="0 0 0" xyz="0 0 -0.082"/>
    <axis xyz="1 0 0"/>
    <limit effort="30" lower="-1.78964425253" upper="1.72828502102" velocity="100"/>
    <parent link="lf_femur_bone_link"/>
    <child link="lf_tibia_bone_link"/>
  </joint>
  <link name="rf_shoulder_link">
    <inertial>
      <mass value="0.00001"/>
      <origin xyz="0 0 0"/>
      <inertia ixx="1.0" ixy="0.0" ixz="0.0" iyy="1.0" iyz="0.0" izz="1.0"/>
    </inertial>
    <collision>
      <origin rpy="0 0 0" xyz="0 0 0"/>
      <geometry>
        <box size="0.028 0.0485 0.065"/>
      </geometry>
    </collision>
    <visual>
      <origin rpy="0 0 0" xyz="0 0 0"/>
      <material name="grey60"/>
      <geometry>
        <mesh filename="package://stikklar_description/meshes/F4.stl" scale="0.001 0.001 0.001"/>
      </geometry>
    </visual>
  </link>
  <joint name="rf_shoulder_joint" type="fixed">
    <origin rpy="1.57079632679 0 -2.35619449019" xyz="0.1 -0.1 0"/>
    <parent link="base_link"/>
    <child link="rf_shoulder_link"/>
  </joint>
  <link name="rf_coxa_bone_link">
    <inertial>
      <mass value="0.00001"/>
      <origin xyz="0 0 0"/>
      <inertia ixx="1.0" ixy="0.0" ixz="0.0" iyy="1.0" iyz="0.0" izz="1.0"/>
    </inertial>
    <visual>
      <origin rpy="0 0 3.14159265359" xyz="0 0 0"/>
      <geometry>
        <mesh filename="package://stikklar_description/meshes/ax12.stl" scale="0.001 0.001 0.001"/>
      </geometry>
      <material name="grey30"/>
    </visual>
    <collision>
      <origin rpy="0 0 0" xyz="0 0 0"/>
      <geometry>
        <box size="0.032 0.040 0.0501"/>
      </geometry>
    </collision>
    <collision>
      <origin rpy="0 3.14159265359 0 " xyz="0 0 -0.0415"/>
      <geometry>
        <box size="0.028 0.0485 0.065"/>
      </geometry>
    </collision>
    <visual>
      <origin rpy="0 3.14159265359 0 " xyz="0 0 -0.0415"/>
      <material name="green"/>
      <geometry>
        <mesh filename="package://stikklar_description/meshes/F3.stl" scale="0.001 0.001 0.001"/>
      </geometry>
    </visual>
    <collision>
      <origin rpy="0 0 1.57079632679 " xyz="0 0 -0.068"/>
      <geometry>
        <box size="0.025 0.0485 0.0375"/>
      </geometry>
    </collision>
    <visual>
      <origin rpy="0 0 1.57079632679 " xyz="0 0 -0.068"/>
      <geometry>
        <mesh filename="package://stikklar_description/meshes/F2.stl" scale="0.001 0.001 0.001"/>
      </geometry>
      <material name="grey60"/>
    </visual>
  </link>
  <joint name="rf_coxa_bone_joint" type="revolute">
    <origin rpy="0 0 0" xyz="0 0 0"/>
    <axis xyz="0 1 0"/>
    <limit effort="30" lower="-2.31119772041" upper="2.29074464324" velocity="100"/>
    <parent link="rf_shoulder_link"/>
    <child link="rf_coxa_bone_link"/>
  </joint>
  <link name="rf_femur_bone_link">
    <inertial>
      <mass value="0.00001"/>
      <origin xyz="0 0 0"/>
      <inertia ixx="1.0" ixy="0.0" ixz="0.0" iyy="1.0" iyz="0.0" izz="1.0"/>
    </inertial>
    <visual>
      <origin rpy="0 0 1.57079632679" xyz="0 0 0"/>
      <geometry>
        <mesh filename="package://stikklar_description/meshes/ax12.stl" scale="0.001 0.001 0.001"/>
      </geometry>
      <material name="grey30"/>
    </visual>
    <collision>
      <origin rpy="0 0 0" xyz="0 0 0"/>
      <geometry>
        <box size="0.032 0.040 0.0501"/>
      </geometry>
    </collision>
    <collision>
      <origin rpy="0 3.14159265359 0" xyz="0 0 -0.0415"/>
      <geometry>
        <box size="0.028 0.0485 0.065"/>
      </geometry>
    </collision>
    <visual>
      <origin rpy="0 3.14159265359 0" xyz="0 0 -0.0415"/>
      <material name="green"/>
      <geometry>
        <mesh filename="package://stikklar_description/meshes/F3.stl" scale="0.001 0.001 0.001"/>
      </geometry>
    </visual>
    <collision>
      <origin rpy="0 0 0" xyz="0.008 0 -0.0415"/>
      <geometry>
        <box size="0.028 0.0485 0.065"/>
      </geometry>
    </collision>
    <visual>
      <origin rpy="0 0 0" xyz="0.008 0 -0.0415"/>
      <material name="green"/>
      <geometry>
        <mesh filename="package://stikklar_description/meshes/F3.stl" scale="0.001 0.001 0.001"/>
      </geometry>
    </visual>
    <visual>
      <origin rpy="3.14159265359 0 -1.57079632679" xyz="0.008 0 -0.082"/>
      <geometry>
        <mesh filename="package://stikklar_description/meshes/ax12.stl" scale="0.001 0.001 0.001"/>
      </geometry>
      <material name="grey30"/>
    </visual>
    <collision>
      <origin rpy="0 0 0" xyz="0.008 0 -0.082"/>
      <geometry>
        <box size="0.032 0.040 0.0501"/>
      </geometry>
    </collision>
  </link>
  <joint name="rf_femur_bone_joint" type="revolute">
    <origin rpy="0 0 0" xyz="0 0 -0.068"/>
    <axis xyz="1 0 0"/>
    <limit effort="30" lower="-1.78964425253" upper="1.72828502102" velocity="100"/>
    <parent link="rf_coxa_bone_link"/>
    <child link="rf_femur_bone_link"/>
  </joint>
  <link name="rf_tibia_bone_link">
    <inertial>
      <mass value="0.00001"/>
      <origin xyz="0 0 0"/>
      <inertia ixx="1.0" ixy="0.0" ixz="0.0" iyy="1.0" iyz="0.0" izz="1.0"/>
    </inertial>
    <collision>
      <origin rpy="0 3.14159265359 1.57079632679" xyz="0.008 0 0"/>
      <geometry>
        <box size="0.028 0.0485 0.065"/>
      </geometry>
    </collision>
    <visual>
      <origin rpy="0 3.14159265359 1.57079632679" xyz="0.008 0 0"/>
      <material name="grey60"/>
      <geometry>
        <mesh filename="package://stikklar_description/meshes/F4.stl" scale="0.001 0.001 0.001"/>
      </geometry>
    </visual>
    <collision>
      <origin rpy="-1.57079632679 0 1.57079632679" xyz="0.008 -0.015 -0.0755"/>
      <geometry>
        <box size="0.04 0.028 0.046"/>
      </geometry>
    </collision>
    <visual>
      <origin rpy="-1.57079632679 0 1.57079632679" xyz="0.008 -0.015 -0.0755"/>
      <geometry>
        <mesh filename="package://stikklar_description/meshes/F1.stl" scale="1 1 1"/>
      </geometry>
      <material name="grey60"/>
    </visual>
    <collision>
      <origin rpy="-0.7853981634 0 0" xyz="0.018 -0.0398 -0.1073"/>
      <geometry>
        <box size="0.02 0.02 0.1"/>
      </geometry>
    </collision>
    <visual>
      <origin rpy="-0.7853981634 0 0" xyz="0.018 -0.0398 -0.1073"/>
      <geometry>
        <box size="0.02 0.02 0.1"/>
      </geometry>
      <material name="grey70"/>
    </visual>
    <collision>
      <origin rpy="-0.7853981634 0 0" xyz="-0.0025 -0.02207 -0.08257"/>
      <geometry>
        <box size="0.02 0.02 0.04"/>
      </geometry>
    </collision>
    <visual>
      <origin rpy="-0.7853981634 0 0" xyz="-0.0025 -0.02207 -0.08257"/>
      <geometry>
        <box size="0.02 0.02 0.04"/>
      </geometry>
      <material name="grey70"/>
    </visual>
    <collision>
      <origin rpy="0 -0.7853981634 1.57079632679" xyz="0.0235 -0.04865 -0.13029"/>
      <geometry>
        <box size="0.028 0.0485 0.065"/>
      </geometry>
    </collision>
    <visual>
      <origin rpy="0 -0.7853981634 1.57079632679" xyz="0.0235 -0.04865 -0.13029"/>
      <material name="green"/>
      <geometry>
        <mesh filename="package://stikklar_description/meshes/F3.stl" scale="0.001 0.001 0.001"/>
      </geometry>
    </visual>
    <visual>
      <origin rpy="3.14159265359 -0.7853981634 -1.57079632679" xyz="0.0235 -0.05078 -0.15928"/>
      <geometry>
        <mesh filename="package://stikklar_description/meshes/ax12.stl" scale="0.001 0.001 0.001"/>
      </geometry>
      <material name="grey30"/>
    </visual>
    <collision>
      <origin rpy="0 0 0" xyz="0.0235 -0.05078 -0.15928"/>
      <geometry>
        <box size="0.032 0.040 0.0501"/>
      </geometry>
    </collision>
  </link>
  <joint name="rf_tibia_bone_joint" type="revolute">
    <origin rpy="0 0 0" xyz="0 0 -0.082"/>
    <axis xyz="1 0 0"/>
    <limit effort="30" lower="-1.78964425253" upper="1.72828502102" velocity="100"/>
    <parent link="rf_femur_bone_link"/>
    <child link="rf_tibia_bone_link"/>
  </joint>
  <link name="lr_shoulder_link">
    <inertial>
      <mass value="0.00001"/>
      <origin xyz="0 0 0"/>
      <inertia ixx="1.0" ixy="0.0" ixz="0.0" iyy="1.0" iyz="0.0" izz="1.0"/>
    </inertial>
    <collision>
      <origin rpy="0 0 0" xyz="0 0 0"/>
      <geometry>
        <box size="0.028 0.0485 0.065"/>
      </geometry>
    </collision>
    <visual>
      <origin rpy="0 0 0" xyz="0 0 0"/>
      <material name="grey60"/>
      <geometry>
        <mesh filename="package://stikklar_description/meshes/F4.stl" scale="0.001 0.001 0.001"/>
      </geometry>
    </visual>
  </link>
  <joint name="lr_shoulder_joint" type="fixed">
    <origin rpy="1.57079632679 0 0.7853981634" xyz="-0.1 0.1 0"/>
    <parent link="base_link"/>
    <child link="lr_shoulder_link"/>
  </joint>
  <link name="lr_coxa_bone_link">
    <inertial>
      <mass value="0.00001"/>
      <origin xyz="0 0 0"/>
      <inertia ixx="1.0" ixy="0.0" ixz="0.0" iyy="1.0" iyz="0.0" izz="1.0"/>
    </inertial>
    <visual>
      <origin rpy="0 0 3.14159265359" xyz="0 0 0"/>
      <geometry>
        <mesh filename="package://stikklar_description/meshes/ax12.stl" scale="0.001 0.001 0.001"/>
      </geometry>
      <material name="grey30"/>
    </visual>
    <collision>
      <origin rpy="0 0 0" xyz="0 0 0"/>
      <geometry>
        <box size="0.032 0.040 0.0501"/>
      </geometry>
    </collision>
    <collision>
      <origin rpy="0 3.14159265359 0 " xyz="0 0 -0.0415"/>
      <geometry>
        <box size="0.028 0.0485 0.065"/>
      </geometry>
    </collision>
    <visual>
      <origin rpy="0 3.14159265359 0 " xyz="0 0 -0.0415"/>
      <material name="green"/>
      <geometry>
        <mesh filename="package://stikklar_description/meshes/F3.stl" scale="0.001 0.001 0.001"/>
      </geometry>
    </visual>
    <collision>
      <origin rpy="0 0 1.57079632679 " xyz="0 0 -0.068"/>
      <geometry>
        <box size="0.025 0.0485 0.0375"/>
      </geometry>
    </collision>
    <visual>
      <origin rpy="0 0 1.57079632679 " xyz="0 0 -0.068"/>
      <geometry>
        <mesh filename="package://stikklar_description/meshes/F2.stl" scale="0.001 0.001 0.001"/>
      </geometry>
      <material name="grey60"/>
    </visual>
  </link>
  <joint name="lr_coxa_bone_joint" type="revolute">
    <origin rpy="0 0 0" xyz="0 0 0"/>
    <axis xyz="0 1 0"/>
    <limit effort="30" lower="-2.31119772041" upper="2.29074464324" velocity="100"/>
    <parent link="lr_shoulder_link"/>
    <child link="lr_coxa_bone_link"/>
  </joint>
  <link name="lr_femur_bone_link">
    <inertial>
      <mass value="0.00001"/>
      <origin xyz="0 0 0"/>
      <inertia ixx="1.0" ixy="0.0" ixz="0.0" iyy="1.0" iyz="0.0" izz="1.0"/>
    </inertial>
    <visual>
      <origin rpy="0 0 1.57079632679" xyz="0 0 0"/>
      <geometry>
        <mesh filename="package://stikklar_description/meshes/ax12.stl" scale="0.001 0.001 0.001"/>
      </geometry>
      <material name="grey30"/>
    </visual>
    <collision>
      <origin rpy="0 0 0" xyz="0 0 0"/>
      <geometry>
        <box size="0.032 0.040 0.0501"/>
      </geometry>
    </collision>
    <collision>
      <origin rpy="0 3.14159265359 0" xyz="0 0 -0.0415"/>
      <geometry>
        <box size="0.028 0.0485 0.065"/>
      </geometry>
    </collision>
    <visual>
      <origin rpy="0 3.14159265359 0" xyz="0 0 -0.0415"/>
      <material name="green"/>
      <geometry>
        <mesh filename="package://stikklar_description/meshes/F3.stl" scale="0.001 0.001 0.001"/>
      </geometry>
    </visual>
    <collision>
      <origin rpy="0 0 0" xyz="0.008 0 -0.0415"/>
      <geometry>
        <box size="0.028 0.0485 0.065"/>
      </geometry>
    </collision>
    <visual>
      <origin rpy="0 0 0" xyz="0.008 0 -0.0415"/>
      <material name="green"/>
      <geometry>
        <mesh filename="package://stikklar_description/meshes/F3.stl" scale="0.001 0.001 0.001"/>
      </geometry>
    </visual>
    <visual>
      <origin rpy="3.14159265359 0 -1.57079632679" xyz="0.008 0 -0.082"/>
      <geometry>
        <mesh filename="package://stikklar_description/meshes/ax12.stl" scale="0.001 0.001 0.001"/>
      </geometry>
      <material name="grey30"/>
    </visual>
    <collision>
      <origin rpy="0 0 0" xyz="0.008 0 -0.082"/>
      <geometry>
        <box size="0.032 0.040 0.0501"/>
      </geometry>
    </collision>
  </link>
  <joint name="lr_femur_bone_joint" type="revolute">
    <origin rpy="0 0 0" xyz="0 0 -0.068"/>
    <axis xyz="1 0 0"/>
    <limit effort="30" lower="-1.78964425253" upper="1.72828502102" velocity="100"/>
    <parent link="lr_coxa_bone_link"/>
    <child link="lr_femur_bone_link"/>
  </joint>
  <link name="lr_tibia_bone_link">
    <inertial>
      <mass value="0.00001"/>
      <origin xyz="0 0 0"/>
      <inertia ixx="1.0" ixy="0.0" ixz="0.0" iyy="1.0" iyz="0.0" izz="1.0"/>
    </inertial>
    <collision>
      <origin rpy="0 3.14159265359 1.57079632679" xyz="0.008 0 0"/>
      <geometry>
        <box size="0.028 0.0485 0.065"/>
      </geometry>
    </collision>
    <visual>
      <origin rpy="0 3.14159265359 1.57079632679" xyz="0.008 0 0"/>
      <material name="grey60"/>
      <geometry>
        <mesh filename="package://stikklar_description/meshes/F4.stl" scale="0.001 0.001 0.001"/>
      </geometry>
    </visual>
    <collision>
      <origin rpy="-1.57079632679 0 1.57079632679" xyz="0.008 -0.015 -0.0755"/>
      <geometry>
        <box size="0.04 0.028 0.046"/>
      </geometry>
    </collision>
    <visual>
      <origin rpy="-1.57079632679 0 1.57079632679" xyz="0.008 -0.015 -0.0755"/>
      <geometry>
        <mesh filename="package://stikklar_description/meshes/F1.stl" scale="1 1 1"/>
      </geometry>
      <material name="grey60"/>
    </visual>
    <collision>
      <origin rpy="-0.7853981634 0 0" xyz="0.018 -0.0398 -0.1073"/>
      <geometry>
        <box size="0.02 0.02 0.1"/>
      </geometry>
    </collision>
    <visual>
      <origin rpy="-0.7853981634 0 0" xyz="0.018 -0.0398 -0.1073"/>
      <geometry>
        <box size="0.02 0.02 0.1"/>
      </geometry>
      <material name="grey70"/>
    </visual>
    <collision>
      <origin rpy="-0.7853981634 0 0" xyz="-0.0025 -0.02207 -0.08257"/>
      <geometry>
        <box size="0.02 0.02 0.04"/>
      </geometry>
    </collision>
    <visual>
      <origin rpy="-0.7853981634 0 0" xyz="-0.0025 -0.02207 -0.08257"/>
      <geometry>
        <box size="0.02 0.02 0.04"/>
      </geometry>
      <material name="grey70"/>
    </visual>
    <collision>
      <origin rpy="0 -0.7853981634 1.57079632679" xyz="0.0235 -0.04865 -0.13029"/>
      <geometry>
        <box size="0.028 0.0485 0.065"/>
      </geometry>
    </collision>
    <visual>
      <origin rpy="0 -0.7853981634 1.57079632679" xyz="0.0235 -0.04865 -0.13029"/>
      <material name="green"/>
      <geometry>
        <mesh filename="package://stikklar_description/meshes/F3.stl" scale="0.001 0.001 0.001"/>
      </geometry>
    </visual>
    <visual>
      <origin rpy="3.14159265359 -0.7853981634 -1.57079632679" xyz="0.0235 -0.05078 -0.15928"/>
      <geometry>
        <mesh filename="package://stikklar_description/meshes/ax12.stl" scale="0.001 0.001 0.001"/>
      </geometry>
      <material name="grey30"/>
    </visual>
    <collision>
      <origin rpy="0 0 0" xyz="0.0235 -0.05078 -0.15928"/>
      <geometry>
        <box size="0.032 0.040 0.0501"/>
      </geometry>
    </collision>
  </link>
  <joint name="lr_tibia_bone_joint" type="revolute">
    <origin rpy="0 0 0" xyz="0 0 -0.082"/>
    <axis xyz="1 0 0"/>
    <limit effort="30" lower="-1.78964425253" upper="1.72828502102" velocity="100"/>
    <parent link="lr_femur_bone_link"/>
    <child link="lr_tibia_bone_link"/>
  </joint>
  <link name="rr_shoulder_link">
    <inertial>
      <mass value="0.00001"/>
      <origin xyz="0 0 0"/>
      <inertia ixx="1.0" ixy="0.0" ixz="0.0" iyy="1.0" iyz="0.0" izz="1.0"/>
    </inertial>
    <collision>
      <origin rpy="0 0 0" xyz="0 0 0"/>
      <geometry>
        <box size="0.028 0.0485 0.065"/>
      </geometry>
    </collision>
    <visual>
      <origin rpy="0 0 0" xyz="0 0 0"/>
      <material name="grey60"/>
      <geometry>
        <mesh filename="package://stikklar_description/meshes/F4.stl" scale="0.001 0.001 0.001"/>
      </geometry>
    </visual>
  </link>
  <joint name="rr_shoulder_joint" type="fixed">
    <origin rpy="1.57079632679 0 2.35619449019" xyz="-0.1 -0.1 0"/>
    <parent link="base_link"/>
    <child link="rr_shoulder_link"/>
  </joint>
  <link name="rr_coxa_bone_link">
    <inertial>
      <mass value="0.00001"/>
      <origin xyz="0 0 0"/>
      <inertia ixx="1.0" ixy="0.0" ixz="0.0" iyy="1.0" iyz="0.0" izz="1.0"/>
    </inertial>
    <visual>
      <origin rpy="0 0 3.14159265359" xyz="0 0 0"/>
      <geometry>
        <mesh filename="package://stikklar_description/meshes/ax12.stl" scale="0.001 0.001 0.001"/>
      </geometry>
      <material name="grey30"/>
    </visual>
    <collision>
      <origin rpy="0 0 0" xyz="0 0 0"/>
      <geometry>
        <box size="0.032 0.040 0.0501"/>
      </geometry>
    </collision>
    <collision>
      <origin rpy="0 3.14159265359 0 " xyz="0 0 -0.0415"/>
      <geometry>
        <box size="0.028 0.0485 0.065"/>
      </geometry>
    </collision>
    <visual>
      <origin rpy="0 3.14159265359 0 " xyz="0 0 -0.0415"/>
      <material name="green"/>
      <geometry>
        <mesh filename="package://stikklar_description/meshes/F3.stl" scale="0.001 0.001 0.001"/>
      </geometry>
    </visual>
    <collision>
      <origin rpy="0 0 1.57079632679 " xyz="0 0 -0.068"/>
      <geometry>
        <box size="0.025 0.0485 0.0375"/>
      </geometry>
    </collision>
    <visual>
      <origin rpy="0 0 1.57079632679 " xyz="0 0 -0.068"/>
      <geometry>
        <mesh filename="package://stikklar_description/meshes/F2.stl" scale="0.001 0.001 0.001"/>
      </geometry>
      <material name="grey60"/>
    </visual>
  </link>
  <joint name="rr_coxa_bone_joint" type="revolute">
    <origin rpy="0 0 0" xyz="0 0 0"/>
    <axis xyz="0 1 0"/>
    <limit effort="30" lower="-2.31119772041" upper="2.29074464324" velocity="100"/>
    <parent link="rr_shoulder_link"/>
    <child link="rr_coxa_bone_link"/>
  </joint>
  <link name="rr_femur_bone_link">
    <inertial>
      <mass value="0.00001"/>
      <origin xyz="0 0 0"/>
      <inertia ixx="1.0" ixy="0.0" ixz="0.0" iyy="1.0" iyz="0.0" izz="1.0"/>
    </inertial>
    <visual>
      <origin rpy="0 0 1.57079632679" xyz="0 0 0"/>
      <geometry>
        <mesh filename="package://stikklar_description/meshes/ax12.stl" scale="0.001 0.001 0.001"/>
      </geometry>
      <material name="grey30"/>
    </visual>
    <collision>
      <origin rpy="0 0 0" xyz="0 0 0"/>
      <geometry>
        <box size="0.032 0.040 0.0501"/>
      </geometry>
    </collision>
    <collision>
      <origin rpy="0 3.14159265359 0" xyz="0 0 -0.0415"/>
      <geometry>
        <box size="0.028 0.0485 0.065"/>
      </geometry>
    </collision>
    <visual>
      <origin rpy="0 3.14159265359 0" xyz="0 0 -0.0415"/>
      <material name="green"/>
      <geometry>
        <mesh filename="package://stikklar_description/meshes/F3.stl" scale="0.001 0.001 0.001"/>
      </geometry>
    </visual>
    <collision>
      <origin rpy="0 0 0" xyz="0.008 0 -0.0415"/>
      <geometry>
        <box size="0.028 0.0485 0.065"/>
      </geometry>
    </collision>
    <visual>
      <origin rpy="0 0 0" xyz="0.008 0 -0.0415"/>
      <material name="green"/>
      <geometry>
        <mesh filename="package://stikklar_description/meshes/F3.stl" scale="0.001 0.001 0.001"/>
      </geometry>
    </visual>
    <visual>
      <origin rpy="3.14159265359 0 -1.57079632679" xyz="0.008 0 -0.082"/>
      <geometry>
        <mesh filename="package://stikklar_description/meshes/ax12.stl" scale="0.001 0.001 0.001"/>
      </geometry>
      <material name="grey30"/>
    </visual>
    <collision>
      <origin rpy="0 0 0" xyz="0.008 0 -0.082"/>
      <geometry>
        <box size="0.032 0.040 0.0501"/>
      </geometry>
    </collision>
  </link>
  <joint name="rr_femur_bone_joint" type="revolute">
    <origin rpy="0 0 0" xyz="0 0 -0.068"/>
    <axis xyz="1 0 0"/>
    <limit effort="30" lower="-1.78964425253" upper="1.72828502102" velocity="100"/>
    <parent link="rr_coxa_bone_link"/>
    <child link="rr_femur_bone_link"/>
  </joint>
  <link name="rr_tibia_bone_link">
    <inertial>
      <mass value="0.00001"/>
      <origin xyz="0 0 0"/>
      <inertia ixx="1.0" ixy="0.0" ixz="0.0" iyy="1.0" iyz="0.0" izz="1.0"/>
    </inertial>
    <collision>
      <origin rpy="0 3.14159265359 1.57079632679" xyz="0.008 0 0"/>
      <geometry>
        <box size="0.028 0.0485 0.065"/>
      </geometry>
    </collision>
    <visual>
      <origin rpy="0 3.14159265359 1.57079632679" xyz="0.008 0 0"/>
      <material name="grey60"/>
      <geometry>
        <mesh filename="package://stikklar_description/meshes/F4.stl" scale="0.001 0.001 0.001"/>
      </geometry>
    </visual>
    <collision>
      <origin rpy="-1.57079632679 0 1.57079632679" xyz="0.008 -0.015 -0.0755"/>
      <geometry>
        <box size="0.04 0.028 0.046"/>
      </geometry>
    </collision>
    <visual>
      <origin rpy="-1.57079632679 0 1.57079632679" xyz="0.008 -0.015 -0.0755"/>
      <geometry>
        <mesh filename="package://stikklar_description/meshes/F1.stl" scale="1 1 1"/>
      </geometry>
      <material name="grey60"/>
    </visual>
    <collision>
      <origin rpy="-0.7853981634 0 0" xyz="0.018 -0.0398 -0.1073"/>
      <geometry>
        <box size="0.02 0.02 0.1"/>
      </geometry>
    </collision>
    <visual>
      <origin rpy="-0.7853981634 0 0" xyz="0.018 -0.0398 -0.1073"/>
      <geometry>
        <box size="0.02 0.02 0.1"/>
      </geometry>
      <material name="grey70"/>
    </visual>
    <collision>
      <origin rpy="-0.7853981634 0 0" xyz="-0.0025 -0.02207 -0.08257"/>
      <geometry>
        <box size="0.02 0.02 0.04"/>
      </geometry>
    </collision>
    <visual>
      <origin rpy="-0.7853981634 0 0" xyz="-0.0025 -0.02207 -0.08257"/>
      <geometry>
        <box size="0.02 0.02 0.04"/>
      </geometry>
      <material name="grey70"/>
    </visual>
    <collision>
      <origin rpy="0 -0.7853981634 1.57079632679" xyz="0.0235 -0.04865 -0.13029"/>
      <geometry>
        <box size="0.028 0.0485 0.065"/>
      </geometry>
    </collision>
    <visual>
      <origin rpy="0 -0.7853981634 1.57079632679" xyz="0.0235 -0.04865 -0.13029"/>
      <material name="green"/>
      <geometry>
        <mesh filename="package://stikklar_description/meshes/F3.stl" scale="0.001 0.001 0.001"/>
      </geometry>
    </visual>
    <visual>
      <origin rpy="3.14159265359 -0.7853981634 -1.57079632679" xyz="0.0235 -0.05078 -0.15928"/>
      <geometry>
        <mesh filename="package://stikklar_description/meshes/ax12.stl" scale="0.001 0.001 0.001"/>
      </geometry>
      <material name="grey30"/>
    </visual>
    <collision>
      <origin rpy="0 0 0" xyz="0.0235 -0.05078 -0.15928"/>
      <geometry>
        <box size="0.032 0.040 0.0501"/>
      </geometry>
    </collision>
  </link>
  <joint name="rr_tibia_bone_joint" type="revolute">
    <origin rpy="0 0 0" xyz="0 0 -0.082"/>
    <axis xyz="1 0 0"/>
    <limit effort="30" lower="-1.78964425253" upper="1.72828502102" velocity="100"/>
    <parent link="rr_femur_bone_link"/>
    <child link="rr_tibia_bone_link"/>
  </joint>
  <link name="neck_base_link">
    <inertial>
      <mass value="0.00001"/>
      <origin xyz="0 0 0"/>
      <inertia ixx="1.0" ixy="0.0" ixz="0.0" iyy="1.0" iyz="0.0" izz="1.0"/>
    </inertial>
    <visual>
      <origin rpy="0 0 0" xyz="0 -0.025 0"/>
      <geometry>
        <mesh filename="package://stikklar_description/meshes/ax12.stl" scale="0.001 0.001 0.001"/>
      </geometry>
      <material name="grey30"/>
    </visual>
    <collision>
      <origin rpy="0 0 0" xyz="0 -0.025 0"/>
      <geometry>
        <box size="0.032 0.040 0.0501"/>
      </geometry>
    </collision>
  </link>
  <joint name="neck_base_joint" type="fixed">
    <origin rpy="1.57079632679 0 0" xyz="0 0 0.0685"/>
    <parent link="base_link"/>
    <child link="neck_base_link"/>
  </joint>
  <link name="neck_pan_link">
    <inertial>
      <mass value="0.00001"/>
      <origin xyz="0 0 0"/>
      <inertia ixx="1.0" ixy="0.0" ixz="0.0" iyy="1.0" iyz="0.0" izz="1.0"/>
    </inertial>
    <!--part_ax12 xyz="0 0 0" rpy="0 0 ${MPI}" /-->
    <collision>
      <origin rpy="0 0 0 " xyz="0 0 0"/>
      <geometry>
        <box size="0.028 0.0485 0.065"/>
      </geometry>
    </collision>
    <visual>
      <origin rpy="0 0 0 " xyz="0 0 0"/>
      <material name="green"/>
      <geometry>
        <mesh filename="package://stikklar_description/meshes/F3.stl" scale="0.001 0.001 0.001"/>
      </geometry>
    </visual>
    <!--part_F2 xyz="0 0 -${L_COXA}" rpy="0 0 ${MPI2} "/-->
  </link>
  <joint name="neck_pan_joint" type="revolute">
    <origin rpy="0 0 0" xyz="0 0 -0.082"/>
    <axis xyz="0 1 0"/>
    <limit effort="30" lower="-2.61799" upper="2.61799" velocity="100"/>
    <parent link="neck_base_link"/>
    <child link="neck_pan_link"/>
  </joint>
  <neck_tilt name="neck_tilt" parent="neck_pan"/>
</robot>

